<?xml version="1.0"?>
<robot xmlns:xacro="http://www.ros.org/wiki/xacro" name="arduinobot">
    <!-- Useful Variables (Properties) -->
    <xacro:property name="PI" value="3.14159265359" />
    <xacro:property name="effort" value="30" />
    <xacro:property name="velocity" value="10" />

    <!-- Useful Macros -->
    <xacro:macro name="default_inertial" params="mass">
        <inertial>
            <mass value="${mass}" />
            <inertia ixx="1.0" ixy="0.0" ixz="0.0"
                     iyy="1.0" iyz="0.0"
                     izz="1.0" />
        </inertial>
    </xacro:macro>
    <xacro:macro name="default_transmission" params="number">
        <transmission name="transmission_${number}">
            <type>transmission_interface/SimpleTransmission</type>
            <joint name="joint_${number}">
                <hardwareInterface>hardware_interface/PositionJointInterface</hardwareInterface>
            </joint>
            <actuator name="motor_${number}">
                <hardwareInterface>hardware_interface/PositionJointInterface</hardwareInterface>
                <mechanicalReduction>1</mechanicalReduction>
            </actuator>
        </transmission>
    </xacro:macro>

    <!-- Links -->
    <link name="world"/>

    <link name="body">
        <visual>
            <origin rpy="1.57 0 0" xyz="0 0 0"/>
            <geometry>
                <mesh filename="package://spiderrobot_description/mesh/BodyCom.stl" scale="0.01 0.01 0.01"/>
            </geometry>
        </visual>
    </link>

    <!-- LEG 1 -->
    <link name="spalla_fl">
        <visual>
            <origin rpy="0 1.57 0.8" xyz="0.315 0.065 0"/>
            <geometry>
                <mesh filename="package://spiderrobot_description/mesh/SpallaCom.stl" scale="0.01 0.01 0.01"/>
            </geometry>
        </visual>
    </link>

    <link name="braccio_fl">
        <visual>
            <origin rpy="0 0 0" xyz="-0.2 -0.15 0.18"/>
            <geometry>
                <mesh filename="package://spiderrobot_description/mesh/Braccio.stl" scale="0.01 0.01 0.01"/>
            </geometry>
        </visual>
    </link>

    <link name="zampa_fl">
        <visual>
            <origin rpy="0 0 0" xyz="-0.93 -0.2 0.25"/>
            <geometry>
                <mesh filename="package://spiderrobot_description/mesh/Zampa.stl" scale="0.01 0.01 0.01"/>
            </geometry>
        </visual>
    </link>

    <!-- LEG 2 -->
    <link name="spalla_fr">
        <visual>
            <origin rpy="0 1.57 -2.37" xyz="-0.66 -0.4 0.45"/>
            <geometry>
                <mesh filename="package://spiderrobot_description/mesh/SpallaCom.stl" scale="0.01 0.01 0.01"/>
            </geometry>
        </visual>
    </link>

<!-- 
    <link name="braccio_fr">
        <visual>
            <origin rpy="0 0 0" xyz="-0.2 -0.15 0.18"/>
            <geometry>
                <mesh filename="package://spiderrobot_description/mesh/Braccio.stl" scale="0.01 0.01 0.01"/>
            </geometry>
        </visual>
    </link>

    <link name="zampa_fr">
        <visual>
            <origin rpy="0 0 0" xyz="-0.93 -0.2 0.25"/>
            <geometry>
                <mesh filename="package://spiderrobot_description/mesh/Zampa.stl" scale="0.01 0.01 0.01"/>
            </geometry>
        </visual>
    </link>

-->

    <!-- Joints --> 
    <joint name="joint_body" type="fixed">
        <parent link="world"/>
        <child link="body"/>
        <origin xyz="0 0 0" rpy="0 0 0"/>
    </joint> 

<!-- LEG 1 -->
    <joint name="joint_1" type="revolute">
        <parent link="body"/>
        <child link="spalla_fl"/>
        <origin xyz="0.655 0.655 0.45"/>
        <axis xyz="0 0 1"/>
        <limit lower="-${PI/2}" upper="${PI/2}" effort="${effort}" velocity="${velocity}"/>
    </joint> 

    <joint name="joint_2" type="revolute">
        <parent link="spalla_fl"/>
        <child link="braccio_fl"/>
        <origin xyz="0.41 0.41 -0.257" rpy="1.57 0 0.8"/>
        <axis xyz="0 0 1"/>
        <limit lower="-${PI/1.7}" upper="${PI/1.7}" effort="${effort}" velocity="${velocity}"/>
    </joint> 

    <joint name="joint_3" type="revolute">
        <parent link="braccio_fl"/>
        <child link="zampa_fl"/>
        <origin xyz="0.65 -0.04 0" rpy="0 0 3.14"/>
        <axis xyz="0 0 1"/>
        <limit lower="-${PI/1.5}" upper="${PI/1.5}" effort="${effort}" velocity="${velocity}"/>
    </joint> 

<!-- LEG 2 -->
    <joint name="joint_4" type="revolute">
        <parent link="body"/>
        <child link="spalla_fr"/>
        <origin xyz="-0.655 -0.655 0"/>
        <axis xyz="0 0 1"/>
        <limit lower="-${PI/2}" upper="${PI/2}" effort="${effort}" velocity="${velocity}"/>
    </joint> 

<!--
    <joint name="joint_2" type="revolute">
        <parent link="spalla_fl"/>
        <child link="braccio_fl"/>
        <origin xyz="0.41 0.41 -0.257" rpy="1.57 0 0.8"/>
        <axis xyz="0 0 1"/>
        <limit lower="-${PI/1.7}" upper="${PI/1.7}" effort="${effort}" velocity="${velocity}"/>
    </joint> 

    <joint name="joint_3" type="revolute">
        <parent link="braccio_fl"/>
        <child link="zampa_fl"/>
        <origin xyz="0.65 -0.04 0" rpy="0 0 3.14"/>
        <axis xyz="0 0 1"/>
        <limit lower="-${PI/1.5}" upper="${PI/1.5}" effort="${effort}" velocity="${velocity}"/>
    </joint> 
-->

</robot>
